<?xml version="1.0"?>
<robot name="mar_robot" xmlns:xacro="http://www.ros.org/wiki/xacro">

  <xacro:property name="base_radius"    value="0.175"/>
  <xacro:property name="base_height"    value="0.08"/>
  <xacro:property name="base_mass"      value="2.0"/>
  <xacro:property name="wheel_radius"   value="0.05"/>
  <xacro:property name="wheel_width"    value="0.04"/>
  <xacro:property name="wheel_mass"     value="0.3"/>
  <xacro:property name="wheel_offset_y" value="0.19"/>
  <xacro:property name="wheel_offset_z" value="-0.01"/>
  <xacro:property name="caster_radius"  value="0.02"/>
  <xacro:property name="caster_mass"    value="0.1"/>

  <link name="base_footprint"/>

  <joint name="base_joint" type="fixed">
    <parent link="base_footprint"/>
    <child  link="base_link"/>
    <origin xyz="0 0 ${wheel_radius}" rpy="0 0 0"/>
  </joint>

  <link name="base_link">
    <visual>
      <geometry><cylinder radius="${base_radius}" length="${base_height}"/></geometry>
      <material name="dark_gray"><color rgba="0.25 0.25 0.25 1.0"/></material>
    </visual>
    <collision>
      <geometry><cylinder radius="${base_radius}" length="${base_height}"/></geometry>
    </collision>
    <inertial>
      <mass value="${base_mass}"/>
      <inertia
        ixx="${(1/12)*base_mass*(3*base_radius*base_radius + base_height*base_height)}"
        iyy="${(1/12)*base_mass*(3*base_radius*base_radius + base_height*base_height)}"
        izz="${(1/2)*base_mass*base_radius*base_radius}"
        ixy="0" ixz="0" iyz="0"/>
    </inertial>
  </link>

  <xacro:macro name="wheel" params="name y_reflect">
    <link name="${name}_wheel_link">
      <visual>
        <geometry><cylinder radius="${wheel_radius}" length="${wheel_width}"/></geometry>
        <material name="black"><color rgba="0.1 0.1 0.1 1.0"/></material>
      </visual>
      <collision>
        <geometry><cylinder radius="${wheel_radius}" length="${wheel_width}"/></geometry>
      </collision>
      <inertial>
        <mass value="${wheel_mass}"/>
        <inertia
          ixx="${(1/12)*wheel_mass*(3*wheel_radius*wheel_radius + wheel_width*wheel_width)}"
          iyy="${(1/12)*wheel_mass*(3*wheel_radius*wheel_radius + wheel_width*wheel_width)}"
          izz="${(1/2)*wheel_mass*wheel_radius*wheel_radius}"
          ixy="0" ixz="0" iyz="0"/>
      </inertial>
    </link>
    <joint name="${name}_wheel_joint" type="continuous">
      <parent link="base_link"/>
      <child  link="${name}_wheel_link"/>
      <origin xyz="0 ${y_reflect * wheel_offset_y} ${wheel_offset_z}" rpy="${-pi/2} 0 0"/>
      <axis xyz="0 0 1"/>
      <dynamics damping="0.1" friction="0.1"/>
    </joint>
  </xacro:macro>

  <xacro:wheel name="left"  y_reflect="1"/>
  <xacro:wheel name="right" y_reflect="-1"/>

  <link name="caster_link">
    <visual>
      <geometry><sphere radius="${caster_radius}"/></geometry>
      <material name="light_gray"><color rgba="0.6 0.6 0.6 1.0"/></material>
    </visual>
    <collision>
      <geometry><sphere radius="${caster_radius}"/></geometry>
    </collision>
    <inertial>
      <mass value="${caster_mass}"/>
      <inertia
        ixx="${(2/5)*caster_mass*caster_radius*caster_radius}"
        iyy="${(2/5)*caster_mass*caster_radius*caster_radius}"
        izz="${(2/5)*caster_mass*caster_radius*caster_radius}"
        ixy="0" ixz="0" iyz="0"/>
    </inertial>
  </link>

  <joint name="caster_joint" type="fixed">
    <parent link="base_link"/>
    <child  link="caster_link"/>
    <origin xyz="${-base_radius + caster_radius} 0 ${-base_height/2 + caster_radius}" rpy="0 0 0"/>
  </joint>

  <link name="lidar_link">
    <visual>
      <geometry><cylinder radius="0.04" length="0.06"/></geometry>
      <material name="blue"><color rgba="0.0 0.4 0.8 1.0"/></material>
    </visual>
    <collision>
      <geometry><cylinder radius="0.04" length="0.06"/></geometry>
    </collision>
    <inertial>
      <mass value="0.1"/>
      <inertia ixx="0.001" iyy="0.001" izz="0.001" ixy="0" ixz="0" iyz="0"/>
    </inertial>
  </link>

  <joint name="lidar_joint" type="fixed">
    <parent link="base_link"/>
    <child  link="lidar_link"/>
    <origin xyz="0 0 ${base_height/2 + 0.03}" rpy="0 0 0"/>
  </joint>

  <link name="imu_link">
    <visual>
      <geometry><box size="0.03 0.03 0.01"/></geometry>
      <material name="green"><color rgba="0.0 0.7 0.2 1.0"/></material>
    </visual>
    <inertial>
      <mass value="0.05"/>
      <inertia ixx="0.0001" iyy="0.0001" izz="0.0001" ixy="0" ixz="0" iyz="0"/>
    </inertial>
  </link>

  <joint name="imu_joint" type="fixed">
    <parent link="base_link"/>
    <child  link="imu_link"/>
    <origin xyz="0 0 ${base_height/2}" rpy="0 0 0"/>
  </joint>

  <link name="camera_link">
    <visual>
      <geometry><box size="0.04 0.06 0.03"/></geometry>
      <material name="blue2"><color rgba="0.0 0.4 0.8 1.0"/></material>
    </visual>
    <inertial>
      <mass value="0.05"/>
      <inertia ixx="0.0001" iyy="0.0001" izz="0.0001" ixy="0" ixz="0" iyz="0"/>
    </inertial>
  </link>

  <joint name="camera_joint" type="fixed">
    <parent link="base_link"/>
    <child  link="camera_link"/>
    <origin xyz="${base_radius - 0.01} 0 ${base_height/2 - 0.01}" rpy="0 0 0"/>
  </joint>

  <link name="camera_optical_link"/>
  <joint name="camera_optical_joint" type="fixed">
    <parent link="camera_link"/>
    <child  link="camera_optical_link"/>
    <origin xyz="0 0 0" rpy="${-pi/2} 0 ${-pi/2}"/>
  </joint>

  <gazebo>
    <plugin filename="gz-sim-diff-drive-system" name="gz::sim::systems::DiffDrive">
      <left_joint>left_wheel_joint</left_joint>
      <right_joint>right_wheel_joint</right_joint>
      <wheel_separation>0.38</wheel_separation>
      <wheel_radius>0.05</wheel_radius>
      <max_linear_velocity>0.5</max_linear_velocity>
      <max_angular_velocity>1.5</max_angular_velocity>
      <topic>cmd_vel</topic>
      <odom_topic>odom</odom_topic>
      <tf_topic>tf</tf_topic>
      <frame_id>odom</frame_id>
      <child_frame_id>base_footprint</child_frame_id>
      <odom_publish_frequency>30</odom_publish_frequency>
    </plugin>
  </gazebo>

  <gazebo>
    <plugin filename="gz-sim-joint-state-publisher-system" name="gz::sim::systems::JointStatePublisher">
      <topic>joint_states</topic>
    </plugin>
  </gazebo>

  <gazebo reference="lidar_link">
    <sensor name="lidar" type="gpu_lidar">
      <topic>scan</topic>
      <update_rate>10</update_rate>
      <always_on>true</always_on>
      <visualize>true</visualize>
      <lidar>
        <scan>
          <horizontal>
            <samples>360</samples>
            <resolution>1</resolution>
            <min_angle>-3.14159</min_angle>
            <max_angle>3.14159</max_angle>
          </horizontal>
        </scan>
        <range><min>0.12</min><max>12.0</max><resolution>0.01</resolution></range>
        <noise><type>gaussian</type><mean>0.0</mean><stddev>0.01</stddev></noise>
      </lidar>
    </sensor>
  </gazebo>

  <gazebo reference="imu_link">
    <sensor name="imu" type="imu">
      <topic>imu</topic>
      <update_rate>100</update_rate>
      <always_on>true</always_on>
    </sensor>
  </gazebo>

  <gazebo reference="left_wheel_link">
    <mu1>1.0</mu1><mu2>1.0</mu2><kp>500000.0</kp><kd>10.0</kd>
  </gazebo>
  <gazebo reference="right_wheel_link">
    <mu1>1.0</mu1><mu2>1.0</mu2><kp>500000.0</kp><kd>10.0</kd>
  </gazebo>
  <gazebo reference="caster_link">
    <mu1>0.01</mu1><mu2>0.01</mu2>
  </gazebo>

</robot>
